Workbook

Sheet Dashboard
F1: 1 | G1: 2 | H1: 3 | I1: 4 | J1: 5 | K1: 6 | L1: 7 | M1: 8 | N1: 9 | O1: 10 | P1: 11 | Q1: 12 | R1: 13 | S1: 14 | T1: 15 | U1: 16 | V1: 17 | W1: 18 | X1: 19 | Y1: 20 | Z1: 21 | AA1: 22 | AB1: 23 | AC1: 24 | AD1: 25 | AE1: 26 | AF1: 27 | AG1: 28 | AH1: 29 | AI1: 30
A2: Billions of Dollars | B2: 2022 | C2: 2023 | D2: 2024 | E2: 2025 | F2: =$E$2+F1&"F" -> 2026F | G2: =$E$2+G1&"F" -> 2027F | H2: =$E$2+H1&"F" -> 2028F | I2: =$E$2+I1&"F" -> 2029F | J2: =$E$2+J1&"F" -> 2030F | K2: =$E$2+K1&"F" -> 2031F | L2: =$E$2+L1&"F" -> 2032F | M2: =$E$2+M1&"F" -> 2033F | ... AI2: =$E$2+AI1&"F" -> 2055F | AJ2: 2056F | AK2: Total | AL2: % Impact (OG GDP) | AM2: % Impact (Change GDP) | AN2: Total after changes
A3: Government revenues | B3: =SUM(B4,B7,B10,B14,B21,B22,B23,B24) -> 4897.399 | C3: =SUM(C4,C7,C10,C14,C21,C22,C23,C24) -> 4440.947 | D3: =SUM(D4,D7,D10,D14,D21,D22,D23,D24) -> 4918.104 | E3: =SUM(E4,E7,E10,E14,E21,E22,E23,E24) -> 5234.315 | F3: =SUM(F4,F7,F10,F14,F21,F22,F23,F24) -> 5386.722 | G3: =SUM(G4,G7,G10,G14,G21,G22,G23,G24) -> 5674.6465 | H3: =SUM(H4,H7,H10,H14,H21,H22,H23,H24) -> 5859.673 | I3: =SUM(I4,I7,I10,I14,I21,I22,I23,I24) -> 6111.06 | ... AJ3: =SUM(AJ4,AJ7,AJ10,AJ14,AJ21,AJ22,AJ23,AJ24) -> 17408.186
A4: Individual Income Taxes | B4: 2632.146 | C4: 2176.481 | D4: 2426.067 | E4: 2656.044 | F4: ='Actual Revenue Progression'!C186 -> 2751.291 | G4: ='Actual Revenue Progression'!D186 -> 2947.025 | H4: ='Actual Revenue Progression'!E186 -> 3044.174 | I4: ='Actual Revenue Progression'!F186 -> 3193.323 | J4: ='Actual Revenue Progression'!G186 -> 3338.979 | K4: ='Actual Revenue Progression'!H186 -> 3461.053 | L4: ='Actual Revenue Progression'!I186 -> 3594.393 | M4: ='Actual Revenue Progression'!J186 -> 3743.854 | ... P4: ='Actual Revenue Progression'!M186 -> 4248.998 | Q4: =P4*1.0409 -> 4422.782 | R4: =Q4*1.0409 -> 4603.6738 | S4: =R4*1.0409 -> 4791.9641 | T4: =S4*1.0409 -> 4987.9554 | U4: =T4*1.0409 -> 5191.9628 | V4: =U4*1.0409 -> 5404.314 | W4: =V4*1.0409 -> 5625.3505 | X4: =W4*1.0409 -> 5855.4273 | Y4: =X4*1.0409 -> 6094.9143 | Z4: =Z64*0.094 -> 6345 | AA4: =Z4*1.04091 -> 6604.5739 | AB4: =AA4*1.04091 -> 6874.7671 | AC4: =AB4*1.04091 -> 7156.0138 | AD4: =AC4*1.04091 -> 7448.7663 | AE4: =AD4*1.04091 -> 7753.4953 | AF4: =AE4*1.04091 -> 8070.6908 | AG4: =AF4*1.04091 -> 8400.8628 | AH4: =AG4*1.04091 -> 8744.5421 | ... AJ4: =AI4*1.04091 -> 9474.6556 | AN4: =AI4+AK5+AK6 -> 22510.714
A5: Income Taxes solution (itemized) | E5: 41.5 | F5: 134.9 | G5: 184.1 | H5: 193.8 | I5: 201.8 | J5: 210.8 | K5: 220.3 | L5: 232 | M5: 241.1 | N5: 249.5 | O5: =N5*1.0444 -> 260.5778 | P5: =O5*1.0444 -> 272.14745 | Q5: =P5*1.0444 -> 284.2308 | R5: =Q5*1.0444 -> 296.85065 | S5: =R5*1.0444 -> 310.03082 | T5: =S5*1.0444 -> 323.79619 | U5: =T5*1.0444 -> 338.17274 | V5: =U5*1.0444 -> 353.18761 | ... AJ5: =AI5*1.0444 -> 648.84586 | AK5: =SUM(E5:AJ5) -> 11303.422 | AL5: =AK5/$AJ$64 -> 0.11811308 | AM5: =AK5/$AJ$68 -> 0.12315201
A6: Include Income from S.corp and LP | E6: 24.5 | F6: 37.1 | G6: 40 | H6: 40.7 | I6: 41.9 | J6: 43.4 | K6: 45.2 | L6: 47 | M6: 48.8 | N6: 51 | O6: =N6*1.034 -> 52.734 | P6: =O6*1.034 -> 54.526956 | Q6: =P6*1.034 -> 56.380873 | R6: =Q6*1.034 -> 58.297822 | S6: =R6*1.034 -> 60.279948 | T6: =S6*1.034 -> 62.329466 | U6: =T6*1.034 -> 64.448668 | V6: =U6*1.034 -> 66.639923 | ... AJ6: =AI6*1.034 -> 106.4197 | AK6: =SUM(E6:AJ6) -> 2105.0109 | AL6: =AK6/$AJ$64 -> 0.021995934 | AM6: =AK6/$AJ$68 -> 0.022934321
A7: Payroll Taxes | B7: 1483.527 | C7: 1614.456 | D7: 1708.926 | E7: 1748.294 | F7: ='Actual Revenue Progression'!C187 -> 1825.573 | G7: ='Actual Revenue Progression'!D187 -> 1896.664 | H7: ='Actual Revenue Progression'!E187 -> 1970.161 | I7: ='Actual Revenue Progression'!F187 -> 2048.466 | J7: ='Actual Revenue Progression'!G187 -> 2131.557 | K7: ='Actual Revenue Progression'!H187 -> 2216.305 | L7: ='Actual Revenue Progression'!I187 -> 2301.556 | M7: ='Actual Revenue Progression'!J187 -> 2388.562 | ... P7: ='Actual Revenue Progression'!M187 -> 2666.066 | Q7: =Q64*0.057 -> 2762.4393 | R7: =R64*0.057 -> 2866.0308 | S7: =S64*0.057 -> 2973.507 | T7: =T64*0.057 -> 3085.0135 | U7: =U64*0.057 -> 3200.7015 | V7: =V64*0.057 -> 3320.7278 | W7: =W64*0.057 -> 3445.2551 | X7: =X64*0.057 -> 3574.4521 | ... AJ7: =AJ64*0.057 -> 5454.9 | AN7: =AI7+AK8+AK9 -> 18517.078
A8: Dividend Tax solution | F8: 118.2 | G8: 122.8 | H8: 127.2 | I8: 131.1 | J8: 135.3 | K8: 278 | L8: 287.7 | M8: 297.5 | N8: 307.4 | O8: =N8*1.037 -> 318.7738 | P8: =O8*1.037 -> 330.56843 | Q8: =P8*1.037 -> 342.79946 | R8: =Q8*1.037 -> 355.48304 | S8: =R8*1.037 -> 368.63592 | T8: =S8*1.037 -> 382.27544 | U8: =T8*1.037 -> 396.41964 | V8: =U8*1.037 -> 411.08716 | ... AJ8: =AI8*1.037 -> 683.65423 | AK8: =SUM(E8:AJ8) -> 12350.487 | AL8: =AK8/$AJ$64 -> 0.1290542 | AM8: =AK8/$AJ$68 -> 0.1345599
A9: Immigration solution | F9: ='Social Security'!$B$22/10 -> 90 | G9: ='Social Security'!$B$22/10 -> 90 | H9: ='Social Security'!$B$22/10 -> 90 | I9: ='Social Security'!$B$22/10 -> 90 | J9: ='Social Security'!$B$22/10 -> 90 | K9: ='Social Security'!$B$22/10 -> 90 | L9: ='Social Security'!$B$22/10 -> 90 | M9: ='Social Security'!$B$22/10 -> 90 | ... O9: ='Social Security'!$B$22/10 -> 90 | AK9: =SUM(E9:AJ9) -> 900 | AL9: =AK9/$AJ$64 -> 0.0094043887 | AM9: =AK9/$AJ$68 -> 0.0098055974
A10: Corporate Income Taxes | B10: 424.865 | C10: 419.584 | D10: 529.867 | E10: 452.089 | F10: ='Actual Revenue Progression'!C188 -> 403.979 | G10: ='Actual Revenue Progression'!D188 -> 419.298 | H10: ='Actual Revenue Progression'!E188 -> 432.534 | I10: ='Actual Revenue Progression'!F188 -> 451.539 | J10: ='Actual Revenue Progression'!G188 -> 477.34 | K10: ='Actual Revenue Progression'!H188 -> 493.465 | L10: ='Actual Revenue Progression'!I188 -> 509.962 | M10: ='Actual Revenue Progression'!J188 -> 525.923 | ... P10: ='Actual Revenue Progression'!M188 -> 575.645 | Q10: =Q64*0.013 -> 630.03002 | R10: =R64*0.013 -> 653.65615 | S10: =S64*0.013 -> 678.16825 | T10: =T64*0.013 -> 703.59956 | U10: =U64*0.013 -> 729.98454 | V10: =V64*0.013 -> 757.35897 | W10: =W64*0.013 -> 785.75993 | X10: =X64*0.013 -> 815.22592 | ... AJ10: =AJ64*0.013 -> 1244.1 | AN10: =AI10+AK11+AK12+AK13 -> 6577.7495 | AQ10: =SUM(AM5:AM25) -> 0.39517476
A11: Halve the GILTI Section 250 Deduction | F11: 60.8 | G11: 64.6 | H11: 65.4 | I11: 65.9 | J11: 68 | K11: =J11*1.0375 -> 70.55 | L11: =K11*1.0375 -> 73.195625 | M11: =L11*1.0375 -> 75.940461 | N11: =M11*1.0375 -> 78.788228 | O11: =N11*1.0375 -> 81.742787 | P11: =O11*1.0375 -> 84.808141 | Q11: =P11*1.0375 -> 87.988447 | R11: =Q11*1.0375 -> 91.288013 | ... Z11: =Y11*1.0375 -> 122.55149 | AA11: =Z11*1.0355 -> 126.90207 | AB11: =AA11*1.0355 -> 131.40709 | AC11: =AB11*1.0355 -> 136.07204 | AD11: =AC11*1.0355 -> 140.9026 | AE11: =AD11*1.0355 -> 145.90464 | AF11: =AE11*1.0355 -> 151.08426 | AG11: =AF11*1.0355 -> 156.44775 | AH11: =AG11*1.0355 -> 162.00165 | ... AJ11: =AI11*1.0355 -> 173.70792 | AK11: =SUM(E11:AJ11) -> 3326.1406 | AL11: =AK11/$AJ$64 -> 0.034755911 | AM11: =AK11/$AJ$68 -> 0.036238662 | AQ11: =SUM(AM31:AM50) -> -0.41578059
A12: Quadruple Stock Buyback Excise Tax | F12: 21 | G12: =F12*1.05 -> 22.05 | H12: =G12*1.05 -> 23.1525 | I12: =H12*1.05 -> 24.310125 | J12: =I12*1.05 -> 25.525631 | K12: =J12*1.05 -> 26.801913 | L12: =K12*1.05 -> 28.142008 | M12: =L12*1.05 -> 29.549109 | N12: =M12*1.05 -> 31.026564 | O12: =N12*1.05 -> 32.577893 | P12: =O12*1.0375 -> 33.799564 | Q12: =P12*1.0375 -> 35.067047 | R12: =Q12*1.0375 -> 36.382061 | S12: =R12*1.0375 -> 37.746389 | T12: =S12*1.0375 -> 39.161878 | U12: =T12*1.0375 -> 40.630449 | V12: =U12*1.0375 -> 42.154091 | W12: =V12*1.0375 -> 43.734869 | ... Z12: =Y12*1.0375 -> 48.841855 | AA12: =Z12*1.0355 -> 50.57574 | AB12: =AA12*1.0355 -> 52.371179 | AC12: =AB12*1.0355 -> 54.230356 | AD12: =AC12*1.0355 -> 56.155534 | AE12: =AD12*1.0355 -> 58.149055 | AF12: =AE12*1.0355 -> 60.213347 | AG12: =AF12*1.0355 -> 62.35092 | AH12: =AG12*1.0355 -> 64.564378 | ... AJ12: =AI12*1.0355 -> 69.229816 | AK12: =SUM(E12:AJ12) -> 1308.8021 | AL12: =AK12/$AJ$64 -> 0.013676093 | AM12: =AK12/$AJ$68 -> 0.01425954
A13: Strengthen Corporate AMT (CAMT) | F13: 11.9 | G13: =F13*1.05 -> 12.495 | H13: =G13*1.05 -> 13.11975 | I13: =H13*1.05 -> 13.775738 | J13: =I13*1.05 -> 14.464524 | K13: =J13*1.05 -> 15.187751 | L13: =K13*1.05 -> 15.947138 | M13: =L13*1.05 -> 16.744495 | N13: =M13*1.05 -> 17.58172 | O13: =N13*1.05 -> 18.460806 | P13: =O13*1.0375 -> 19.153086 | Q13: =P13*1.0375 -> 19.871327 | R13: =Q13*1.0375 -> 20.616501 | S13: =R13*1.0375 -> 21.38962 | T13: =S13*1.0375 -> 22.191731 | U13: =T13*1.0375 -> 23.023921 | V13: =U13*1.0375 -> 23.887318 | W13: =V13*1.0375 -> 24.783092 | ... Z13: =Y13*1.0375 -> 27.677051 | AA13: =Z13*1.0355 -> 28.659586 | AB13: =AA13*1.0355 -> 29.677002 | AC13: =AB13*1.0355 -> 30.730535 | AD13: =AC13*1.0355 -> 31.821469 | AE13: =AD13*1.0355 -> 32.951131 | AF13: =AE13*1.0355 -> 34.120896 | AG13: =AF13*1.0355 -> 35.332188 | AH13: =AG13*1.0355 -> 36.586481 | ... AJ13: =AI13*1.0355 -> 39.230229 | AK13: =SUM(E13:AJ13) -> 741.65452 | AL13: =AK13/$AJ$64 -> 0.007749786 | AM13: =AK13/$AJ$68 -> 0.0080804062
A14: Excise taxes | B14: 87.728 | C14: 75.802 | D14: 101.435 | E14: 105.936 | F14: ='Actual Revenue Progression'!C191 -> 108.344 | G14: ='Actual Revenue Progression'!D191 -> 108.196 | H14: ='Actual Revenue Progression'!E191 -> 106.722 | I14: ='Actual Revenue Progression'!F191 -> 108.028 | J14: ='Actual Revenue Progression'!G191 -> 110.013 | K14: ='Actual Revenue Progression'!H191 -> 109.556 | L14: ='Actual Revenue Progression'!I191 -> 110.831 | M14: ='Actual Revenue Progression'!J191 -> 112.45 | ... P14: ='Actual Revenue Progression'!M191 -> 118.642 | Q14: =(0.009*0.29)*Q64 -> 126.49064 | R14: =(0.009*0.29)*R64 -> 131.23404 | S14: =(0.009*0.29)*S64 -> 136.15532 | T14: =(0.009*0.29)*T64 -> 141.26114 | U14: =(0.009*0.29)*U64 -> 146.55844 | V14: =(0.009*0.29)*V64 -> 152.05438 | W14: =(0.009*0.29)*W64 -> 157.75642 | X14: =(0.009*0.29)*X64 -> 163.67228 | ... Z14: =(0.009*0.29)*Z64 -> 176.175 | AA14: =(0.01*0.29)*AA64 -> 202.69912 | AB14: =(0.01*0.29)*AB64 -> 209.89494 | AC14: =(0.01*0.29)*AC64 -> 217.34621 | AD14: =(0.01*0.29)*AD64 -> 225.06201 | AE14: =(0.01*0.29)*AE64 -> 233.05171 | AF14: =(0.01*0.29)*AF64 -> 241.32504 | AG14: =(0.01*0.29)*AG64 -> 249.89208 | AH14: =(0.01*0.29)*AH64 -> 258.76325 | ... AJ14: =(0.01*0.29)*AJ64 -> 277.53 | AN14: =AI14+SUM(AK15:AK19) -> 2506.3631
A15: OPTION 69 | F15: 6.6 | G15: 8.9 | H15: 9.4 | I15: 9.8 | J15: 10.2 | K15: 10.6 | L15: 11 | M15: 11.5 | N15: 11.9 | O15: 12.4 | P15: 12.8 | Q15: 13.2 | R15: 13.6 | S15: 14 | T15: 14.4 | U15: 14.8 | V15: 15.2 | W15: 15.6 | X15: 16 | Y15: 16.4 | Z15: 16.8 | AA15: 17.2 | AB15: 17.6 | AC15: 18 | AD15: 18.4 | AE15: 18.8 | AF15: 19.2 | AG15: 19.6 | AH15: 20 | AI15: 20.4 | AJ15: 20.4 | AK15: =SUM(E15:AJ15) -> 454.7 | AL15: =AK15/$AJ$64 -> 0.0047513062 | AM15: =AK15/$AJ$68 -> 0.0049540057
A16: OPTION 70 | F16: 3.1 | G16: 4.4 | H16: 4.8 | I16: 5 | J16: 5.3 | K16: 5.5 | L16: 5.8 | M16: 5.9 | N16: 6 | O16: 5.9 | P16: 5.8 | Q16: 5.7 | R16: 5.6 | S16: 5.5 | T16: 5.4 | U16: 5.3 | V16: 5.2 | W16: 5.1 | X16: 5 | Y16: 4.9 | Z16: 4.8 | AA16: 4.7 | AB16: 4.6 | AC16: 4.5 | AD16: 4.4 | AE16: 4.3 | AF16: 4.2 | AG16: 4.1 | AH16: 4 | AI16: 3.9 | AJ16: 3.9 | AK16: =SUM(E16:AJ16) -> 152.6 | AL16: =AK16/$AJ$64 -> 0.0015945664 | AM16: =AK16/$AJ$68 -> 0.0016625935
A17: OPTION 71 | F17: 14.6 | G17: 20.5 | H17: 20.9 | I17: 21.3 | J17: 21.7 | K17: 22.1 | L17: 22.3 | M17: 22.5 | N17: 22.7 | O17: 22.9 | P17: 22.3275 | Q17: 21.755 | R17: 21.1825 | S17: 20.61 | T17: 20.0375 | U17: 19.465 | V17: 18.8925 | W17: 18.32 | X17: 17.7475 | Y17: 17.175 | Z17: 16.6025 | AA17: 16.03 | AB17: 15.4575 | AC17: 14.885 | AD17: 14.3125 | AE17: 13.74 | AF17: 13.1675 | AG17: 12.595 | AH17: 12.0225 | AI17: 11.45 | AJ17: 11.45 | AK17: =SUM(E17:AJ17) -> 560.725 | AL17: =AK17/$AJ$64 -> 0.0058591954 | AM17: =AK17/$AJ$68 -> 0.0061091595
A18: Space | J18: 0.255165 | K18: 0.3317145 | L18: 0.43122885 | M18: 0.56059751 | N18: 0.72877676 | O18: 0.94740978 | P18: 1.2316327 | Q18: 1.6011225 | R18: 2.0814593 | S18: 2.7058971 | T18: 3.5176662 | U18: 4.2211994 | V18: 5.0654393 | W18: 6.0785272 | X18: 7.2942326 | Y18: 8.7530792 | Z18: 10.503695 | AA18: 12.604434 | AB18: 15.125321 | AC18: 18.150385 | AD18: 21.780462 | AE18: 23.958508 | AF18: 26.354359 | AG18: 28.989795 | AH18: 31.888774 | AI18: 35.077652 | AJ18: 35.077652 | AK18: =SUM(E18:AJ18) -> 305.31618 | AL18: =AK18/$AJ$64 -> 0.0031903468 | AM18: =AK18/$AJ$68 -> 0.0033264529
A19: EV | F19: =F87*F88*0.02 -> 1.1362 | G19: =G87*G88*0.02 -> 2.4807845 | H19: =H87*H88*0.02 -> 3.8613523 | I19: =I87*I88*0.02 -> 5.2779034 | J19: =J87*J88*0.02 -> 6.7304379 | K19: =K87*K88*0.02 -> 8.2189557 | L19: =L87*L88*0.02 -> 9.7434569 | M19: =M87*M88*0.02 -> 11.303941 | ... AJ19: =AJ87*AJ88*0.02 -> 0 | AK19: =SUM(E19:AJ19) -> 765.07262 | AL19: =AK19/$AJ$64 -> 0.0079944892 | AM19: =AK19/$AJ$68 -> 0.0083355489
A20: Financial transaction | F20: 10.3 | G20: 25 | H20: 32.7 | I20: 35.9 | J20: 37.6 | K20: 39.1 | L20: 40.6 | M20: 42.2 | N20: 43.8 | O20: =N20*1.05 -> 45.99 | P20: =O20*1.05 -> 48.2895 | Q20: =P20*1.05 -> 50.703975 | R20: =Q20*1.05 -> 53.239174 | S20: =R20*1.05 -> 55.901132 | T20: =S20*1.05 -> 58.696189 | U20: =T20*1.05 -> 61.630999 | V20: =U20*1.05 -> 64.712548 | ... AJ20: =AI20*1.05 -> 128.12642 | AK20: =SUM(E20:AJ20) -> 2078.0548 | AL20: =AK20/$AJ$64 -> 0.021714261 | AM20: =AK20/$AJ$68 -> 0.022640632
A21: Federal Reserve remittances | B21: 106.674 | C21: 0.581 | D21: 3.131 | E21: 5.49 | F21: ='Actual Revenue Progression'!C192 -> 7.853 | G21: ='Actual Revenue Progression'!D192 -> 8.557 | H21: ='Actual Revenue Progression'!E192 -> 9.158 | I21: ='Actual Revenue Progression'!F192 -> 14.822 | J21: ='Actual Revenue Progression'!G192 -> 37.887 | K21: ='Actual Revenue Progression'!H192 -> 93.912 | L21: ='Actual Revenue Progression'!I192 -> 129.707 | M21: ='Actual Revenue Progression'!J192 -> 140.534 | ... P21: ='Actual Revenue Progression'!M192 -> 176.402 | Q21: =(0.009*0.43)*Q64 -> 187.55509 | R21: =(0.009*0.43)*R64 -> 194.58841 | S21: =(0.009*0.43)*S64 -> 201.88547 | T21: =(0.009*0.43)*T64 -> 209.45618 | U21: =(0.009*0.43)*U64 -> 217.31078 | V21: =(0.009*0.43)*V64 -> 225.45994 | W21: =(0.009*0.43)*W64 -> 233.91469 | X21: =(0.009*0.43)*X64 -> 242.68649 | ... Z21: =(0.009*0.43)*Z64 -> 261.225 | AA21: =(0.01*0.43)*AA64 -> 300.55388 | AB21: =(0.01*0.43)*AB64 -> 311.22354 | AC21: =(0.01*0.43)*AC64 -> 322.27197 | AD21: =(0.01*0.43)*AD64 -> 333.71263 | AE21: =(0.01*0.43)*AE64 -> 345.55943 | AF21: =(0.01*0.43)*AF64 -> 357.82679 | AG21: =(0.01*0.43)*AG64 -> 370.52964 | AH21: =(0.01*0.43)*AH64 -> 383.68344 | ... AJ21: =(0.01*0.43)*AJ64 -> 411.51 | AN21: =SUM(AI21,AI23:AI25) -> 638.63401
A22: Customs duties | B22: 99.908 | C22: 80.338 | D22: 77.037 | E22: 195 | F22: ='Actual Revenue Progression'!C189/2 -> 209.194 | G22: ='Actual Revenue Progression'!D189/2 -> 210.5515 | H22: ='Actual Revenue Progression'!E189/2 -> 211.795 | I22: ='Actual Revenue Progression'!F189/2 -> 208.729 | J22: ='Actual Revenue Progression'!G189/2 -> 206.2135 | K22: ='Actual Revenue Progression'!H189/2 -> 202.621 | L22: ='Actual Revenue Progression'!I189/2 -> 194.6535 | M22: ='Actual Revenue Progression'!J189/2 -> 191.1535 | ... P22: ='Actual Revenue Progression'!M189/2 -> 201.178 | Q22: =Q64*0.003 -> 145.39154 | R22: =R64*0.003 -> 150.84373 | S22: =S64*0.003 -> 156.50037 | T22: =T64*0.003 -> 162.36913 | U22: =U64*0.003 -> 168.45797 | V22: =V64*0.003 -> 174.77515 | W22: =W64*0.003 -> 181.32921 | X22: =X64*0.003 -> 188.12906 | ... AJ22: =AJ64*0.003 -> 287.1 | AN22: =AI22 -> 277.18898
A23: Estate and gift taxes | B23: 32.55 | C23: 33.668 | D23: 31.616 | E23: 29.462 | F23: ='Actual Revenue Progression'!C193 -> 36.405 | G23: ='Actual Revenue Progression'!D193 -> 35.207 | H23: ='Actual Revenue Progression'!E193 -> 35.861 | I23: ='Actual Revenue Progression'!F193 -> 35.609 | J23: ='Actual Revenue Progression'!G193 -> 36.166 | K23: ='Actual Revenue Progression'!H193 -> 37.441 | L23: ='Actual Revenue Progression'!I193 -> 39.228 | M23: ='Actual Revenue Progression'!J193 -> 41.391 | ... P23: ='Actual Revenue Progression'!M193 -> 50.675 | Q23: =(0.009*0.12)*Q64 -> 52.340956 | R23: =(0.009*0.12)*R64 -> 54.303741 | S23: =(0.009*0.12)*S64 -> 56.340132 | T23: =(0.009*0.12)*T64 -> 58.452887 | U23: =(0.009*0.12)*U64 -> 60.64487 | V23: =(0.009*0.12)*V64 -> 62.919053 | W23: =(0.009*0.12)*W64 -> 65.278517 | X23: =(0.009*0.12)*X64 -> 67.726461 | ... Z23: =(0.009*0.12)*Z64 -> 72.9 | AA23: =(0.01*0.12)*AA64 -> 83.8755 | AB23: =(0.01*0.12)*AB64 -> 86.85308 | AC23: =(0.01*0.12)*AC64 -> 89.936365 | AD23: =(0.01*0.12)*AD64 -> 93.129106 | AE23: =(0.01*0.12)*AE64 -> 96.435189 | AF23: =(0.01*0.12)*AF64 -> 99.858638 | AG23: =(0.01*0.12)*AG64 -> 103.40362 | AH23: =(0.01*0.12)*AH64 -> 107.07445 | ... AJ23: =(0.01*0.12)*AJ64 -> 114.84
A24: Miscellaneous fees and fines | B24: 30.001 | C24: 40.037 | D24: 40.025 | E24: 42 | F24: ='Actual Revenue Progression'!C194 -> 44.083 | G24: ='Actual Revenue Progression'!D194 -> 49.148 | H24: ='Actual Revenue Progression'!E194 -> 49.268 | I24: ='Actual Revenue Progression'!F194 -> 50.544 | J24: ='Actual Revenue Progression'!G194 -> 50.63 | K24: ='Actual Revenue Progression'!H194 -> 52.519 | L24: ='Actual Revenue Progression'!I194 -> 54.698 | M24: ='Actual Revenue Progression'!J194 -> 56.455 | ... P24: ='Actual Revenue Progression'!M194 -> 61.971 | Q24: =(0.009*0.13)*Q64 -> 56.702702 | R24: =(0.009*0.13)*R64 -> 58.829053 | S24: =(0.009*0.13)*S64 -> 61.035143 | T24: =(0.009*0.13)*T64 -> 63.323961 | U24: =(0.009*0.13)*U64 -> 65.698609 | V24: =(0.009*0.13)*V64 -> 68.162307 | W24: =(0.009*0.13)*W64 -> 70.718393 | X24: =(0.009*0.13)*X64 -> 73.370333 | ... Z24: =(0.009*0.13)*Z64 -> 78.975 | AA24: =(0.01*0.15)*AA64 -> 104.84437 | AB24: =(0.01*0.15)*AB64 -> 108.56635 | AC24: =(0.01*0.15)*AC64 -> 112.42046 | AD24: =(0.01*0.15)*AD64 -> 116.41138 | AE24: =(0.01*0.15)*AE64 -> 120.54399 | AF24: =(0.01*0.15)*AF64 -> 124.8233 | AG24: =(0.01*0.15)*AG64 -> 129.25452 | AH24: =(0.01*0.15)*AH64 -> 133.84306 | ... AJ24: =(0.01*0.15)*AJ64 -> 143.55
A25: Change to CPI-U | F25: -0.1 | G25: -0.1 | H25: -0.1 | I25: -0.2 | J25: -0.2 | K25: -0.2 | L25: -0.8 | M25: -0.9 | N25: -1.1 | O25: =N25*1.1 -> -1.21 | P25: =O25*1.1 -> -1.331 | Q25: =P25*1.1 -> -1.4641 | R25: =Q25*1.1 -> -1.61051 | S25: =R25*1.1 -> -1.771561 | T25: =S25*1.1 -> -1.9487171 | U25: =T25*1.1 -> -2.1435888 | V25: =U25*1.1 -> -2.3579477 | ... AJ25: =AI25*1.1 -> -8.9543024 | AK25: =SUM(F25:AI25) -> -81.143024 | AL25: =AK25/$AJ$64 -> -0.00084788949 | AM25: =AK25/$AJ$68 -> -0.00088406203
A26: https://www.usaspending.gov/
A28: Government Spending | B28: =SUM(B29,B42,B51) -> 6778.258 | C28: =SUM(C29,C42,C51) -> 6479.281 | D28: =SUM(D29,D42,D51) -> 7105.486 | E28: =SUM(E29,E42,E51) -> 7009.775 | F28: =SUM(F29,F42,F51) -> 7450 | G28: =SUM(G29,G42,G51) -> 7773 | H28: =SUM(H29,H42,H51) -> 8151 | I28: =SUM(I29,I42,I51) -> 8339 | ... AJ28: =SUM(AJ29,AJ42,AJ51) -> 24351.347
A29: Mandatory Spending | B29: =SUM(B30,B33,B35,B39,B41) -> 4637.851 | C29: =SUM(C30,C33,C35,C39,C41) -> 4102.875 | D29: =SUM(D30,D33,D35,D39,D41) -> 4415.432 | E29: =SUM(E30,E33,E35,E39,E41) -> 4167.46 | F29: =SUM(F30,F33,F35,F39,F41) -> 4530 | G29: =SUM(G30,G33,G35,G39,G41) -> 4783 | H29: =SUM(H30,H33,H35,H39,H41) -> 5004 | I29: =SUM(I30,I33,I35,I39,I41) -> 5067 | ... AJ29: =SUM(AJ30,AJ33,AJ35,AJ39,AJ41) -> 13821.56
A30: Medicare | B30: 974.649 | C30: 1015.87 | D30: 1043.79 | E30: 1179.972 | F30: ='Gov outlays'!C12 -> 1287 | G30: ='Gov outlays'!D12 -> 1374 | H30: ='Gov outlays'!E12 -> 1533 | I30: ='Gov outlays'!F12 -> 1470 | J30: ='Gov outlays'!G12 -> 1649 | K30: ='Gov outlays'!H12 -> 1753 | L30: ='Gov outlays'!I12 -> 1867 | M30: ='Gov outlays'!J12 -> 2123 | ... P30: ='Gov outlays'!M12 -> 2421 | Q30: =P30*1.0346 -> 2504.7666 | R30: =Q30*1.0346 -> 2591.4315 | S30: =R30*1.0346 -> 2681.0951 | T30: =S30*1.0346 -> 2773.8609 | U30: =T30*1.0346 -> 2869.8365 | V30: =U30*1.0346 -> 2969.1329 | W30: =V30*1.0346 -> 3071.8649 | X30: =W30*1.0346 -> 3178.1514 | Y30: =X30*1.0346 -> 3288.1154 | Z30: =Z$64*(70%*7.2%) -> 3402 | AA30: =Z30*1.0452 -> 3555.7704 | AB30: =AA30*1.0452 -> 3716.4912 | AC30: =AB30*1.0452 -> 3884.4766 | AD30: =AC30*1.0452 -> 4060.055 | AE30: =AD30*1.0452 -> 4243.5695 | AF30: =AE30*1.0452 -> 4435.3788 | AG30: =AF30*1.0452 -> 4635.8579 | AH30: =AG30*1.0452 -> 4845.3987 | ... AJ30: =AI30*1.0452 -> 5293.3221 | AN30: =AI30+AK31+AK32+AI33+AK34 -> -10580.723
A31: Federal Medicare Spending Cap | G31: 0 | H31: -62.650371 | I31: -102.74992 | J31: -149.72295 | K31: -163.55611 | L31: -178.59271 | M31: -194.93368 | N31: -212.68827 | O31: -231.97465 | P31: -252.92064 | Q31: -275.66451 | R31: -300.35579 | S31: -327.15621 | T31: -356.24065 | U31: -387.79819 | V31: -422.03328 | W31: -459.16695 | X31: -499.43814 | Y31: -543.10514 | Z31: -590.4471 | AA31: -641.76577 | AB31: -697.38723 | AC31: -757.66388 | AD31: -822.9765 | AE31: -893.73653 | AF31: -970.38854 | AG31: -1053.4128 | AH31: -1143.3282 | AI31: -1240.6953 | AJ31: -1240.6953 | AK31: =SUM(F31:AJ31) -> -15173.245 | AL31: =AK31/$AJ$64 -> -0.15855011 | AM31: =AK31/$AJ$68 -> -0.16531415
A32: Decrease drug price | F32: -48.540756 | G32: -69.406318 | H32: -83.403712 | I32: -96.701236 | J32: -109.33388 | K32: -102.88941 | L32: -96.767163 | M32: -90.951027 | N32: -85.425698 | O32: -80.176636 | P32: -75.190026 | Q32: -70.452747 | R32: -65.952332 | S32: -61.676937 | T32: -57.615313 | U32: -53.756769 | V32: -50.091153 | W32: -46.608818 | X32: -43.300599 | Y32: -40.157791 | Z32: -37.172124 | AA32: -34.33574 | AB32: -31.641175 | AC32: -29.081339 | AD32: -26.649494 | AE32: -24.339241 | AF32: -22.144502 | AG32: -20.059499 | AH32: -18.078746 | AI32: -16.197031 | AJ32: -16.197031 | AK32: =SUM(F32:AJ32) -> -1704.2942 | AL32: =AK32/$AJ$64 -> -0.017808717 | AM32: =AK32/$AJ$68 -> -0.01856847
A33: Medicaid | B33: 591.949 | C33: 615.772 | D33: 617.517 | E33: 668.134 | F33: ='Gov outlays'!C13 -> 708 | G33: ='Gov outlays'!D13 -> 726 | H33: ='Gov outlays'!E13 -> 746 | I33: ='Gov outlays'!F13 -> 754 | J33: ='Gov outlays'!G13 -> 777 | K33: ='Gov outlays'!H13 -> 804 | L33: ='Gov outlays'!I13 -> 834 | M33: ='Gov outlays'!J13 -> 870 | ... P33: ='Gov outlays'!M13 -> 981 | Q33: =P33*1.0404 -> 1020.6324 | R33: =Q33*1.0404 -> 1061.8659 | S33: =R33*1.0404 -> 1104.7653 | T33: =S33*1.0404 -> 1149.3979 | U33: =T33*1.0404 -> 1195.8335 | V33: =U33*1.0404 -> 1244.1452 | W33: =V33*1.0404 -> 1294.4087 | X33: =W33*1.0404 -> 1346.7028 | Y33: =X33*1.0404 -> 1401.1096 | Z33: =Z$64*(30%*7.2%) -> 1458 | AA33: =Z33*1.0452 -> 1523.9016 | AB33: =AA33*1.0452 -> 1592.782 | AC33: =AB33*1.0452 -> 1664.7757 | AD33: =AC33*1.0452 -> 1740.0236 | AE33: =AD33*1.0452 -> 1818.6726 | AF33: =AE33*1.0452 -> 1900.8766 | AG33: =AF33*1.0452 -> 1986.7962 | AH33: =AG33*1.0452 -> 2076.5994 | ... AJ33: =AI33*1.0452 -> 2268.5666
A34: Change to CPI-U | F34: -0.4 | G34: -0.9 | H34: -1.4 | I34: -1.8 | J34: -2.5 | K34: -3.4 | L34: -6.5 | M34: -5 | N34: -5.6 | O34: =N34*1.2 -> -6.72 | P34: =O34*1.2 -> -8.064 | Q34: =P34*1.2 -> -9.6768 | R34: =Q34*1.2 -> -11.61216 | S34: =R34*1.2 -> -13.934592 | T34: =S34*1.2 -> -16.72151 | U34: =T34*1.2 -> -20.065812 | V34: =U34*1.2 -> -24.078975 | W34: =V34*1.3 -> -31.302667 | X34: =W34*1.3 -> -40.693468 | Y34: =X34*1.06 -> -43.135076 | Z34: =Y34*1.06 -> -45.72318 | AA34: =Z34*1.06 -> -48.466571 | AB34: =AA34*1.06 -> -51.374565 | AC34: =AB34*1.06 -> -54.457039 | AD34: =AC34*1.06 -> -57.724462 | AE34: =AD34*1.06 -> -61.187929 | AF34: =AE34*1.06 -> -64.859205 | ... AJ34: =AI34*1.06 -> -81.883252 | AK34: =SUM(F34:AJ34) -> -938.05618 | AL34: =AK34/$AJ$64 -> -0.0098020499 | AM34: =AK34/$AJ$68 -> -0.010220224
A35: Social Security | B35: 1212.487 | C35: 1347.961 | D35: 1454.382 | E35: 1575.309 | F35: ='Gov outlays'!C11 -> 1666 | G35: ='Gov outlays'!D11 -> 1769 | H35: ='Gov outlays'!E11 -> 1875 | I35: ='Gov outlays'!F11 -> 1979 | J35: ='Gov outlays'!G11 -> 2083 | K35: ='Gov outlays'!H11 -> 2190 | L35: ='Gov outlays'!I11 -> 2298 | M35: ='Gov outlays'!J11 -> 2409 | ... P35: ='Gov outlays'!M11 -> 2747 | Q35: =P35*1.0361 -> 2846.1667 | R35: =Q35*1.0361 -> 2948.9133 | S35: =R35*1.0361 -> 3055.3691 | T35: =S35*1.0361 -> 3165.6679 | U35: =T35*1.0361 -> 3279.9485 | V35: =U35*1.0361 -> 3398.3547 | W35: =V35*1.0361 -> 3521.0353 | X35: =W35*1.0361 -> 3648.1446 | Y35: =X35*1.0361 -> 3779.8427 | Z35: =Z$64*0.058 -> 3915 | AA35: =Z35*1.0373 -> 4061.0295 | AB35: =AA35*1.0373 -> 4212.5059 | AC35: =AB35*1.0373 -> 4369.6324 | AD35: =AC35*1.0373 -> 4532.6197 | AE35: =AD35*1.0373 -> 4701.6864 | AF35: =AE35*1.0373 -> 4877.0593 | AG35: =AF35*1.0373 -> 5058.9736 | AH35: =AG35*1.0373 -> 5247.6733 | ... AJ35: =AI35*1.0373 -> 5646.4508 | AN35: =AI35+AK36+AK37 -> -7646.4718
A36: Reduce SS for high-incomers | G36: -1 | H36: -2 | I36: -5 | J36: -8 | K36: -13 | L36: -20 | M36: -29 | N36: -39 | O36: =N36*1.28 -> -49.92 | P36: =O36*1.28 -> -63.8976 | Q36: =P36*1.28 -> -81.788928 | R36: =Q36*1.28 -> -104.68983 | S36: =R36*1.2 -> -125.62779 | T36: =S36*1.2 -> -150.75335 | U36: =T36*1.2 -> -180.90402 | V36: =U36*1.2 -> -217.08483 | W36: =V36*1.15 -> -249.64755 | X36: =W36*1.15 -> -287.09468 | Y36: =X36*1.15 -> -330.15889 | Z36: =Y36*1.15 -> -379.68272 | AA36: =Z36*1.1 -> -417.65099 | AB36: =AA36*1.1 -> -459.41609 | AC36: =AB36*1.1 -> -505.3577 | AD36: =AC36*1.1 -> -555.89347 | AE36: =AD36*1.07 -> -594.80601 | AF36: =AE36*1.07 -> -636.44243 | AG36: =AF36*1.07 -> -680.9934 | AH36: =AG36*1.07 -> -728.66294 | AI36: =AH36*1.07 -> -779.66935 | AJ36: =AI36*1.07 -> -834.2462 | AK36: =SUM(F36:AJ36) -> -8531.3888 | AL36: =AK36/$AJ$64 -> -0.089147218 | AM36: =AK36/$AJ$68 -> -0.092950404
A37: Change to CPI-U | F37: =-2.9-0.8 -> -3.7 | G37: =-7.2-1.9 -> -9.1 | H37: =-11.8-3.1 -> -14.9 | I37: =-16.6-4.4 -> -21 | J37: =-21.9-5.4 -> -27.3 | K37: =-27.3-6.7 -> -34 | L37: =-33-8 -> -41 | M37: =-38.8-9.4 -> -48.2 | N37: =-44.7-10.8 -> -55.5 | O37: =N37*1.13 -> -62.715 | P37: =O37*1.13 -> -70.86795 | Q37: =P37*1.13 -> -80.080783 | R37: =Q37*1.13 -> -90.491285 | S37: =R37*1.13 -> -102.25515 | T37: =S37*1.13 -> -115.54832 | U37: =T37*1.13 -> -130.5696 | V37: =U37*1.13 -> -147.54365 | W37: =V37*1.13 -> -166.72433 | X37: =W37*1.06 -> -176.72779 | Y37: =X37*1.06 -> -187.33145 | Z37: =Y37*1.06 -> -198.57134 | AA37: =Z37*1.06 -> -210.48562 | AB37: =AA37*1.06 -> -223.11476 | AC37: =AB37*1.06 -> -236.50165 | AD37: =AC37*1.06 -> -250.69174 | AE37: =AD37*1.06 -> -265.73325 | ... AJ37: =AI37*1.06 -> -355.61103 | AK37: =SUM(F37:AJ37) -> -4558.4945 | AL37: =AK37/$AJ$64 -> -0.047633171 | AM37: =AK37/$AJ$68 -> -0.049665291 | AN37: =AL25+AL34+AL37 -> -0.058283111
AN38: =-AM25--AM34--AM37 -> -0.059001452
A39: Other MandaSpending | B39: 1858.766 | C39: 1123.272 | D39: 1299.743 | E39: 1114.045 | F39: ='Gov outlays'!C14 -> 1281 | G39: ='Gov outlays'!D14 -> 1327 | H39: ='Gov outlays'!E14 -> 1284 | I39: ='Gov outlays'!F14 -> 1326 | J39: ='Gov outlays'!G14 -> 1371 | K39: ='Gov outlays'!H14 -> 1377 | L39: ='Gov outlays'!I14 -> 1400 | M39: ='Gov outlays'!J14 -> 1466 | ... P39: ='Gov outlays'!M14 -> 1555 | Q39: =Q$64*0.024 -> 1163.1323 | R39: =R$64*0.024 -> 1206.7498 | S39: =S$64*0.024 -> 1252.0029 | T39: =T$64*0.024 -> 1298.953 | U39: =U$64*0.024 -> 1347.6638 | V39: =V$64*0.024 -> 1398.2012 | W39: =W$64*0.024 -> 1450.6337 | X39: =X$64*0.024 -> 1505.0325 | ... Z39: =Z$64*0.024 -> 1620 | AA39: =AA$64*0.023 -> 1607.6137 | AB39: =AB$64*0.023 -> 1664.684 | AC39: =AC$64*0.023 -> 1723.7803 | AD39: =AD$64*0.023 -> 1784.9745 | AE39: =AE$64*0.023 -> 1848.3411 | AF39: =AF$64*0.023 -> 1913.9572 | AG39: =AG$64*0.023 -> 1981.9027 | AH39: =AH$64*0.023 -> 2052.2603 | ... AJ39: =AJ$64*0.023 -> 2201.1 | AN39: =AI39+AK40 -> -1588.8845
A40: Emergency Spending | AK40: -3714 | AL40: =AK40/$AJ$64 -> -0.038808777 | AM40: =AK40/$AJ$68 -> -0.040464432
A41: Offsetting Receipts | E41: ='Gov outlays'!B15 -> -370 | F41: ='Gov outlays'!C15 -> -412 | G41: ='Gov outlays'!D15 -> -413 | H41: ='Gov outlays'!E15 -> -434 | I41: ='Gov outlays'!F15 -> -462 | J41: ='Gov outlays'!G15 -> -504 | K41: ='Gov outlays'!H15 -> -541 | L41: ='Gov outlays'!I15 -> -564 | ... P41: ='Gov outlays'!M15 -> -675 | Q41: =P41*1.0437 -> -704.4975 | R41: =Q41*1.0437 -> -735.28404 | S41: =R41*1.0437 -> -767.41595 | T41: =S41*1.0437 -> -800.95203 | U41: =T41*1.0437 -> -835.95363 | V41: =U41*1.0437 -> -872.48481 | W41: =V41*1.0437 -> -910.61239 | X41: =W41*1.0437 -> -950.40616 | ... AJ41: =AI41*1.0437 -> -1587.8791
...

Sheet Charts
B2: Individual Income Taxes | C2: 2656.044 | D2: 21755.449
B3: Payroll Taxes | C3: 1748.294 | D3: 17833.424
B4: Corporate Income Taxes | C4: 452.089 | D4: 6295.5815
B5: Excise taxes | C5: 105.936 | D5: 2435.5355
B6: Customs duties | C6: 195 | D6: 230.99081
B7: Others | C7: 77 | D7: 639
B10: Health | C10: 1848.106 | D10: -9241.9477
B11: Social Security | C11: 1575.309 | D11: -6456.6145
B12: Other MandaSpending | C12: 1114.045 | D12: -1588.8845
B13: Defense | C13: 892.5 | D13: -1280.6217
B14: Non-defense | C14: 979.877 | D14: 2028.5073
B51: 2025 | C51: 2026F | D51: 2027F | E51: 2028F | F51: 2029F | G51: 2030F | H51: 2031F | I51: 2032F | J51: 2033F | K51: 2034F | L51: 2035F | M51: 2036F | N51: 2037F | O51: 2038F | P51: 2039F | Q51: 2040F | R51: 2041F | S51: 2042F | T51: 2043F | U51: 2044F | V51: 2045F | W51: 2046F | X51: 2047F | Y51: 2048F | Z51: 2049F | AA51: 2050F | AB51: 2051F | AC51: 2052F | AD51: 2053F | AE51: 2054F | AF51: 2055F | AG51: 2056F
B52: -1775.46 | C52: -2063.278 | D52: -2098.3535 | E52: -2291.327 | F52: -2227.94 | G52: -2408.2145 | H52: -2489.128 | I52: -2632.9715 | J52: -2970.6775 | K52: -3008.873 | L52: -2973.186 | M52: -3317.423 | N52: -2998.2002 | O52: -3109.4852 | P52: -3225.1706 | Q52: -3345.4434 | R52: -3470.4992 | S52: -3600.5422 | T52: -3735.7862 | U52: -3876.4549 | V52: -4022.7819 | W52: -4214.1884 | X52: -4230.1121 | Y52: -4473.1752 | Z52: -4730.1535 | AA52: -5001.8409 | AB52: -5289.0762 | AC52: -5592.746 | AD52: -5913.7873 | AE52: -6253.1903 | AF52: -6612.0016 | AG52: -6943.161
B53: -1775.46 | C53: -2471.989 | D53: -2339.9114 | E53: -2496.9928 | F53: -2176.6949 | G53: -2333.2804 | H53: -2193.5983 | I53: -2300.093 | J53: -2803.5863 | K53: -2698.4969 | L53: -2442.7208 | M53: -3020.4539 | N53: -2192.3099 | O53: -2208.9456 | P53: -2225.1367 | Q53: -2234.3175 | R53: -2235.5223 | S53: -2227.0147 | T53: -2215.4569 | U53: -2204.5613 | V53: -2192.6965 | W53: -2209.1143 | X53: -1883.0124 | Y53: -1987.0076 | Z53: -2094.052 | AA53: -2204.0009 | AB53: -2335.5156 | AC53: -2472.9785 | AD53: -2616.5891 | AE53: -2766.5444 | AF53: -2923.0372 | AG53: -3153.9046
B55: 2025 | C55: 2026F | D55: 2027F | E55: 2028F | F55: 2029F | G55: 2030F | H55: 2031F | I55: 2032F | J55: 2033F | K55: 2034F | L55: 2035F | M55: 2036F | N55: 2037F | O55: 2038F | P55: 2039F | Q55: 2040F | R55: 2041F | S55: 2042F | T55: 2043F | U55: 2044F | V55: 2045F | W55: 2046F | X55: 2047F | Y55: 2048F | Z55: 2049F | AA55: 2050F | AB55: 2051F | AC55: 2052F | AD55: 2053F | AE55: 2054F | AF55: 2055F
B56: 37637.553 | C56: 32305.278 | D56: 34215.353 | E56: 36305.327 | F56: 38310.94 | G56: 40487.215 | H56: 42732.128 | I56: 45115.971 | J56: 47833.677 | K56: 50583.873 | L56: 53297.186 | M56: 56354.423 | N56: 58875.41 | O56: 61991.459 | P56: 65273.264 | Q56: 69663.884 | R56: 73586.783 | S56: 77731.905 | T56: 82111.892 | U56: 86740.102 | V56: 91630.659 | W56: 96835.085 | X56: 102153.5 | Y56: 108002.36 | Z56: 114185.78 | AA56: 120722.91 | AB56: 127633.96 | AC56: 134940.34 | AD56: 142664.63 | AE56: 150830.76 | AF56: 159463.99
B57: 37637.553 | C57: 32713.989 | D57: 34456.911 | E57: 36510.993 | F57: 38259.695 | G57: 40412.28 | H57: 42436.598 | I57: 44783.093 | J57: 47666.586 | K57: 50273.497 | L57: 52766.721 | M57: 56057.454 | N57: 58069.52 | O57: 61090.919 | P57: 64273.23 | Q57: 68552.758 | R57: 72351.806 | S57: 76358.378 | T57: 80591.563 | U57: 85068.209 | V57: 89800.573 | W57: 94830.011 | X57: 99806.4 | Y57: 105516.19 | Z57: 111549.68 | AA57: 117925.07 | AB57: 124680.4 | AC57: 131820.57 | AD57: 139367.44 | AE57: 147344.12 | AF57: 155775.02

Sheet GDP
B1: 1996 | C1: 1997 | D1: 1998 | E1: 1999 | F1: 2000 | G1: 2001 | H1: 2002 | I1: 2003 | J1: 2004 | K1: 2005 | L1: 2006 | M1: 2007 | N1: 2008 | O1: 2009 | P1: 2010 | Q1: 2011 | R1: 2012 | S1: 2013 | T1: 2014 | U1: 2015 | V1: 2016 | W1: 2017 | X1: 2018 | Y1: 2019 | Z1: 2020 | AA1: 2021 | AB1: 2022 | AC1: 2023 | AD1: 2024 | AE1: 2025 | AF1: 2026 | AG1: 2027 | AH1: 2028 | AI1: 2029 | AJ1: 2030 | AK1: 2031 | AL1: 2032 | AM1: 2033 | AN1: 2034 | AO1: 2035 | AP1: 2036 | AQ1: 2037 | AR1: 2038 | AS1: 2039 | AT1: 2040 | AU1: 2041 | AV1: 2042 | AW1: 2043 | AX1: 2044 | AY1: 2045 | AZ1: 2046 | BA1: 2047 | BB1: 2048 | BC1: 2049 | BD1: 2050 | BE1: 2051 | BF1: 2052 | BG1: 2053 | BH1: 2054 | BI1: 2055 | BJ1: 2056
A2: Real GDP (trillions of 2017 dollars) | B2: 11.8436 | C2: 12.3703 | D2: 12.9249 | E2: 13.5438 | F2: 14.096 | G2: 14.2307 | H2: 14.4727 | I2: 14.8773 | J2: 15.4498 | K2: 15.988 | L2: 16.4332 | M2: 16.7625 | N2: 16.7815 | O2: 16.3491 | P2: 16.7898 | Q2: 17.0524 | R2: 17.4428 | S2: 17.8122 | T2: 18.2617 | U2: 18.7996 | V2: 19.1417 | W2: 19.6121 | X2: 20.1939 | Y2: 20.7157 | Z2: 20.2845 | AA2: 21.5324 | AB2: 22.0759 | AC2: 22.7237 | AD2: 23.3584 | AE2: 23.8303 | AF2: 24.3938 | AG2: 24.8477 | AH2: 25.2963 | AI2: 25.7402 | AJ2: 26.1994 | AK2: 26.6647 | AL2: 27.134 | AM2: 27.6137 | AN2: 28.1022 | AO2: 28.6004 | AP2: 29.1055 | AQ2: 29.6149 | AR2: 30.1317 | AS2: 30.6532 | AT2: 31.1886 | AU2: 31.7296 | AV2: 32.273 | AW2: 32.8231 | AX2: 33.3782 | AY2: 33.9277 | AZ2: 34.4741 | BA2: 35.0228 | BB2: 35.5741 | BC2: 36.1278 | BD2: 36.6814 | BE2: 37.2368 | BF2: 37.7955 | BG2: 38.3596 | BH2: 38.9296 | BI2: 39.507 | BJ2: 40.0935
A3: Nominal GDP (trillions of dollars, by calendar year) | B3: 8.0731 | C3: 8.5776 | D3: 9.0628 | E3: 9.6312 | F3: 10.251 | G3: 10.5819 | H3: 10.9291 | I3: 11.4565 | J3: 12.2172 | K3: 13.0392 | L3: 13.8156 | M3: 14.4743 | N3: 14.7699 | O3: 14.4781 | P3: 15.049 | Q3: 15.5997 | R3: 16.254 | S3: 16.8807 | T3: 17.6081 | U3: 18.295 | V3: 18.8049 | W3: 19.6121 | X3: 20.6565 | Y3: 21.54 | Z3: 21.3753 | AA3: 23.7257 | AB3: 26.0546 | AC3: 27.8115 | AD3: 29.298 | AE3: 30.7052 | AF3: 32.2742 | AG3: 33.6515 | AH3: 35.0019 | AI3: 36.3507 | AJ3: 37.7425 | AK3: 39.1748 | AL3: 40.6504 | AM3: 42.1854 | AN3: 43.7766 | AO3: 45.4309 | AP3: 47.1467 | AQ3: 48.9235 | AR3: 50.7696 | AS3: 52.6807 | AT3: 54.6739 | AU3: 56.7366 | AV3: 58.8639 | AW3: 61.0661 | AX3: 63.342 | AY3: 65.6728 | AZ3: 68.0645 | BA3: 70.5302 | BB3: 73.0732 | BC3: 75.695 | BD3: 78.3926 | BE3: 81.1722 | BF3: 84.04 | BG3: 87.0037 | BH3: 90.0672 | BI3: 93.2378 | BJ3: 96.5216
A4: Growth of the GDP price index | B4: 1.828 | C4: 1.733 | D4: 1.101 | E4: 1.401 | F4: 2.285 | G4: 2.305 | H4: 1.498 | I4: 2.002 | J4: 2.671 | K4: 3.121 | L4: 3.111 | M4: 2.708 | N4: 1.882 | O4: 0.658 | P4: 1.199 | Q4: 2.061 | R4: 1.869 | S4: 1.727 | T4: 1.741 | U4: 0.871 | V4: 0.957 | W4: 1.824 | X4: 2.29 | Y4: 1.653 | Z4: 1.362 | AA4: 4.54 | AB4: 7.125 | AC4: 3.688 | AD4: 2.485 | AE4: 2.726 | AF4: 2.676 | AG4: 2.363 | AH4: 2.168 | AI4: 2.062 | AJ4: 2.009 | AK4: 1.983 | AL4: 1.972 | AM4: 1.973 | AN4: 1.967 | AO4: 1.971 | AP4: 1.975 | AQ4: 1.983 | AR4: 1.993 | AS4: 1.998 | AT4: 2.001 | AU4: 2.003 | AV4: 2.002 | AW4: 2.002 | AX4: 2.002 | AY4: 2 | AZ4: 1.999 | BA4: 1.999 | BB4: 1.999 | BC4: 2 | BD4: 2 | BE4: 2.001 | BF4: 2.002 | BG4: 2.004 | BH4: 2.005 | BI4: 2.007 | BJ4: 2.007
A5: Real GDP (trillions of dollars) | B5: =B3/(1+B4/100) -> 7.928173 | C5: =C3/(1+C4/100) -> 8.4314824 | D5: =D3/(1+D4/100) -> 8.9641052 | E5: =E3/(1+E4/100) -> 9.4981312 | F5: =F3/(1+F4/100) -> 10.021997 | G5: =G3/(1+G4/100) -> 10.343483 | H5: =H3/(1+H4/100) -> 10.767798 | I5: =I3/(1+I4/100) -> 11.231643 | ... AA5: =AA3/(1+AA4/100) -> 22.695332 | AB5: 26.770514 | AC5: 28.424722 | AD5: 29.825182 | AE5: 31.49007 | AF5: =AF3/(1+AF4/100) -> 31.433052 | AG5: =AG3/(1+AG4/100) -> 32.874672 | AH5: =AH3/(1+AH4/100) -> 34.259161 | AI5: =AI3/(1+AI4/100) -> 35.616292 | AJ5: =AJ3/(1+AJ4/100) -> 36.999186 | AK5: =AK3/(1+AK4/100) -> 38.413069 | AL5: =AL3/(1+AL4/100) -> 39.864276 | AM5: =AM3/(1+AM4/100) -> 41.369186 | ... BJ5: =BJ3/(1+BJ4/100) -> 94.622526
A6: Growth% real | C6: =(C5-B5)/B5 -> 0.063483657 | D6: =(D5-C5)/C5 -> 0.063170717 | E6: =(E5-D5)/D5 -> 0.059573819 | F6: =(F5-E5)/E5 -> 0.055154658 | G6: =(G5-F5)/F5 -> 0.032077973 | H6: =(H5-G5)/G5 -> 0.041022513 | I6: =(I5-H5)/H5 -> 0.043076971 | J6: =(J5-I5)/I5 -> 0.059450376 | ... BJ6: =(BJ5-BI5)/BI5 -> 0.035219621
A7: Growth% nominal | C7: =(C3-B3)/B3 -> 0.062491484 | D7: =(D3-C3)/C3 -> 0.056565939 | E7: =(E3-D3)/D3 -> 0.062717924 | F7: =(F3-E3)/E3 -> 0.064353352 | G7: =(G3-F3)/F3 -> 0.032279778 | H7: =(H3-G3)/G3 -> 0.032810743 | I7: =(I3-H3)/H3 -> 0.04825649 | J7: =(J3-I3)/I3 -> 0.066398987 | ... BJ7: =(BJ3-BI3)/BI3 -> 0.035219621
A9: Spending multiplier | B9: IncomeTax multiplier | D9: Corp Tax | E9: Payroll Tax | F9: infra | G9: others
A10: 2 | B10: 1.5 | D10: 0.4 | E10: 1.3 | F10: 1.2 | G10: 1
A11: 1 | B11: 0.75 | D11: 0.2 | E11: 0.8 | F11: 0.85 | G11: 0.8
A12: 0.5 | B12: 0.1 | D12: 0 | E12: 0.3 | F12: 0.5 | G12: 0.6
B14: 2026 | C14: 2027 | D14: 2028 | E14: 2029 | F14: 2030 | G14: 2031 | H14: 2032 | I14: 2033 | J14: 2034 | K14: 2035 | L14: 2036 | M14: 2037 | N14: 2038 | O14: 2039 | P14: 2040 | Q14: 2041 | R14: 2042 | S14: 2043 | T14: 2044 | U14: 2045 | V14: 2046 | W14: 2047 | X14: 2048 | Y14: 2049 | Z14: 2050 | AA14: 2051 | AB14: 2052 | AC14: 2053 | AD14: 2054 | AE14: 2055 | AF14: 2056
B15: bad | C15: bad | D15: bad | E15: normal | F15: normal | G15: normal | H15: good | I15: good | J15: good | K15: normal | L15: normal | M15: normal | N15: normal | O15: bad | P15: bad | Q15: bad | R15: normal | S15: normal | T15: normal | U15: good | V15: good | W15: good | X15: normal | Y15: normal | Z15: normal | AA15: normal | AB15: bad | AC15: bad | AD15: bad | AE15: normal | AF15: normal
A16: Spending multiplier | B16: {=_xlfn.IFS(B$15="bad", $A$10, B$15="normal", $A$11, B$15="good", $A$12)} -> 2 | C16: {=_xlfn.IFS(C$15="bad", $A$10, C$15="normal", $A$11, C$15="good", $A$12)} -> 2 | D16: {=_xlfn.IFS(D$15="bad", $A$10, D$15="normal", $A$11, D$15="good", $A$12)} -> 2 | E16: {=_xlfn.IFS(E$15="bad", $A$10, E$15="normal", $A$11, E$15="good", $A$12)} -> 1 | F16: {=_xlfn.IFS(F$15="bad", $A$10, F$15="normal", $A$11, F$15="good", $A$12)} -> 1 | G16: {=_xlfn.IFS(G$15="bad", $A$10, G$15="normal", $A$11, G$15="good", $A$12)} -> 1 | H16: {=_xlfn.IFS(H$15="bad", $A$10, H$15="normal", $A$11, H$15="good", $A$12)} -> 0.5 | I16: {=_xlfn.IFS(I$15="bad", $A$10, I$15="normal", $A$11, I$15="good", $A$12)} -> 0.5 | ... AF16: {=_xlfn.IFS(AF$15="bad", $A$10, AF$15="normal", $A$11, AF$15="good", $A$12)} -> 1
A17: IncomeTax multiplier | B17: {=_xlfn.IFS(B$15="bad", $B$10, B$15="normal", $B$11, B$15="good", $B$12)} -> 1.5 | C17: {=_xlfn.IFS(C$15="bad", $B$10, C$15="normal", $B$11, C$15="good", $B$12)} -> 1.5 | D17: {=_xlfn.IFS(D$15="bad", $B$10, D$15="normal", $B$11, D$15="good", $B$12)} -> 1.5 | E17: {=_xlfn.IFS(E$15="bad", $B$10, E$15="normal", $B$11, E$15="good", $B$12)} -> 0.75 | F17: {=_xlfn.IFS(F$15="bad", $B$10, F$15="normal", $B$11, F$15="good", $B$12)} -> 0.75 | G17: {=_xlfn.IFS(G$15="bad", $B$10, G$15="normal", $B$11, G$15="good", $B$12)} -> 0.75 | H17: {=_xlfn.IFS(H$15="bad", $B$10, H$15="normal", $B$11, H$15="good", $B$12)} -> 0.1 | I17: {=_xlfn.IFS(I$15="bad", $B$10, I$15="normal", $B$11, I$15="good", $B$12)} -> 0.1 | ... AF17: {=_xlfn.IFS(AF$15="bad", $B$10, AF$15="normal", $B$11, AF$15="good", $B$12)} -> 0.75
A18: Corp Tax | B18: {=_xlfn.IFS(B$15="bad", $D$10, B$15="normal", $D$11, B$15="good", $D$12)} -> 0.4 | C18: {=_xlfn.IFS(C$15="bad", $D$10, C$15="normal", $D$11, C$15="good", $D$12)} -> 0.4 | D18: {=_xlfn.IFS(D$15="bad", $D$10, D$15="normal", $D$11, D$15="good", $D$12)} -> 0.4 | E18: {=_xlfn.IFS(E$15="bad", $D$10, E$15="normal", $D$11, E$15="good", $D$12)} -> 0.2 | F18: {=_xlfn.IFS(F$15="bad", $D$10, F$15="normal", $D$11, F$15="good", $D$12)} -> 0.2 | G18: {=_xlfn.IFS(G$15="bad", $D$10, G$15="normal", $D$11, G$15="good", $D$12)} -> 0.2 | H18: {=_xlfn.IFS(H$15="bad", $D$10, H$15="normal", $D$11, H$15="good", $D$12)} -> 0 | I18: {=_xlfn.IFS(I$15="bad", $D$10, I$15="normal", $D$11, I$15="good", $D$12)} -> 0 | ... AF18: {=_xlfn.IFS(AF$15="bad", $D$10, AF$15="normal", $D$11, AF$15="good", $D$12)} -> 0.2
A19: Payroll Tax | B19: {=_xlfn.IFS(B$15="bad", $E$10, B$15="normal", $E$11, B$15="good", $E$12)} -> 1.3 | C19: {=_xlfn.IFS(C$15="bad", $E$10, C$15="normal", $E$11, C$15="good", $E$12)} -> 1.3 | D19: {=_xlfn.IFS(D$15="bad", $E$10, D$15="normal", $E$11, D$15="good", $E$12)} -> 1.3 | E19: {=_xlfn.IFS(E$15="bad", $E$10, E$15="normal", $E$11, E$15="good", $E$12)} -> 0.8 | F19: {=_xlfn.IFS(F$15="bad", $E$10, F$15="normal", $E$11, F$15="good", $E$12)} -> 0.8 | G19: {=_xlfn.IFS(G$15="bad", $E$10, G$15="normal", $E$11, G$15="good", $E$12)} -> 0.8 | H19: {=_xlfn.IFS(H$15="bad", $E$10, H$15="normal", $E$11, H$15="good", $E$12)} -> 0.3 | I19: {=_xlfn.IFS(I$15="bad", $E$10, I$15="normal", $E$11, I$15="good", $E$12)} -> 0.3 | ... AF19: {=_xlfn.IFS(AF$15="bad", $E$10, AF$15="normal", $E$11, AF$15="good", $E$12)} -> 0.8
A20: Infrastructure spending | B20: {=_xlfn.IFS(B$15="bad", $F$10, B$15="normal", $F$11, B$15="good", $F$12)} -> 1.2 | C20: {=_xlfn.IFS(C$15="bad", $F$10, C$15="normal", $F$11, C$15="good", $F$12)} -> 1.2 | D20: {=_xlfn.IFS(D$15="bad", $F$10, D$15="normal", $F$11, D$15="good", $F$12)} -> 1.2 | E20: {=_xlfn.IFS(E$15="bad", $F$10, E$15="normal", $F$11, E$15="good", $F$12)} -> 0.85 | F20: {=_xlfn.IFS(F$15="bad", $F$10, F$15="normal", $F$11, F$15="good", $F$12)} -> 0.85 | G20: {=_xlfn.IFS(G$15="bad", $F$10, G$15="normal", $F$11, G$15="good", $F$12)} -> 0.85 | H20: {=_xlfn.IFS(H$15="bad", $F$10, H$15="normal", $F$11, H$15="good", $F$12)} -> 0.5 | I20: {=_xlfn.IFS(I$15="bad", $F$10, I$15="normal", $F$11, I$15="good", $F$12)} -> 0.5 | ... AF20: {=_xlfn.IFS(AF$15="bad", $F$10, AF$15="normal", $F$11, AF$15="good", $F$12)} -> 0.85
A21: Others Taxes | B21: {=_xlfn.IFS(B$15="bad", $G$10, B$15="normal", $G$11, B$15="good", $G$12)} -> 1 | C21: {=_xlfn.IFS(C$15="bad", $G$10, C$15="normal", $G$11, C$15="good", $G$12)} -> 1 | D21: {=_xlfn.IFS(D$15="bad", $G$10, D$15="normal", $G$11, D$15="good", $G$12)} -> 1 | E21: {=_xlfn.IFS(E$15="bad", $G$10, E$15="normal", $G$11, E$15="good", $G$12)} -> 0.8 | F21: {=_xlfn.IFS(F$15="bad", $G$10, F$15="normal", $G$11, F$15="good", $G$12)} -> 0.8 | G21: {=_xlfn.IFS(G$15="bad", $G$10, G$15="normal", $G$11, G$15="good", $G$12)} -> 0.8 | H21: {=_xlfn.IFS(H$15="bad", $G$10, H$15="normal", $G$11, H$15="good", $G$12)} -> 0.6 | I21: {=_xlfn.IFS(I$15="bad", $G$10, I$15="normal", $G$11, I$15="good", $G$12)} -> 0.6 | ... AF21: {=_xlfn.IFS(AF$15="bad", $G$10, AF$15="normal", $G$11, AF$15="good", $G$12)} -> 0.8
A24: https://www.crfb.org/papers/comparing-fiscal-multipliers
A25: https://www.cbo.gov/sites/default/files/114th-congress-2015-2016/workingpaper/49925-FiscalMultiplier_1.pdf
A26: https://www.richmondfed.org/publications/research/econ_focus/2018/q4/jargon_alert
A27: Year | B27: 2022 | C27: 2023 | D27: 2024 | E27: 2025 | F27: 2026 | G27: 2027 | H27: 2028 | I27: 2029 | J27: 2030 | K27: 2031 | L27: 2032 | M27: 2033 | N27: 2034 | O27: 2035 | P27: 2036
A28: GDP | B28: 25565.375 | C28: 27397.95 | D28: 28947.9 | E28: 30330.329 | F28: 31902.006 | G28: 33315.187 | H28: 34665.785 | I28: 36010.049 | J28: 37390.673 | K28: 38812.821 | L28: 40276.526 | M28: 41795.93 | N28: 43373.323 | O28: 45011.5 | P28: 46712.142
A31: Table 2-1. CBO’s Economic Projections for Calendar Years 2026 to 2036
A32: Percent
F33: Annual average
B34: Estimated, 2025 | C34: 2026 | D34: 2027 | E34: 2028 | F34: 2029– 2030 | G34: 2031– 2036
B35: Change from fourth quarter to fourth quarter
A36: Gross domestic product
A37: Real | B37: 1.9 | C37: 2.2 | D37: 1.8 | E37: 1.8 | F37: 1.8 | G37: 1.8
A38: Nominal | B38: 5 | C38: 4.8 | D38: 4.1 | E38: 3.9 | F38: 3.8 | G38: 3.8
A39: Inflation
A40: PCE price index | B40: 2.8 | C40: 2.7 | D40: 2.3 | E40: 2.1 | F40: 2 | G40: 2
A41: Core PCE price index | B41: 2.9 | C41: 2.8 | D41: 2.3 | E41: 2.2 | F41: 2 | G41: 2
A42: Consumer price index | B42: 3 | C42: 2.8 | D42: 2.4 | E42: 2.3 | F42: 2.3 | G42: 2.3
A43: Core consumer price index | B43: 3.1 | C43: 3 | D43: 2.4 | E43: 2.3 | F43: 2.3 | G43: 2.3
A44: GDP price index | B44: 3 | C44: 2.5 | D44: 2.3 | E44: 2.1 | F44: 2 | G44: 2
A45: Employment cost index | B45: 3.4 | C45: 3.5 | D45: 3.2 | E45: 3.1 | F45: 3 | G45: 2.9
A46: Payroll employment (average monthly change, in thousands) | B46: 70 | C46: 105 | D46: 31 | E46: 42 | F46: 43 | G46: 45
...

Sheet Tariff
A1: Tariff Tracker: 2026 Trump Tariffs & Trade War by the Numbers
A2: Calendar Year | B2: 2025 | C2: 2026 | D2: 2027 | E2: 2028 | F2: 2029 | G2: 2030 | H2: 2031 | I2: 2032 | J2: 2033 | K2: 2034 | L2: 2035 | M2: 2026-2035
A3: Section 232 Tariffs | B3: 23.2 | C3: 42.8 | D3: 43.6 | E3: 45.3 | F3: 46 | G3: 47.7 | H3: 49.5 | I3: 50.9 | J3: 53.1 | K3: 54.9 | L3: 55.9 | M3: 489.6
A4: Section 232 Steel and Aluminum | B4: 6.2 | C4: 7.3 | D4: 7.4 | E4: 7.9 | F4: 8.1 | G4: 8.4 | H4: 8.8 | I4: 8.9 | J4: 9.5 | K4: 9.7 | L4: 9.8 | M4: 85.7
A5: Section 232 Autos and Auto Parts | B5: 17.1 | C5: 28.2 | D5: 28.5 | E5: 29.2 | F5: 29.7 | G5: 30.7 | H5: 31.8 | I5: 32.8 | J5: 34 | K5: 35.1 | L5: 35.9 | M5: 315.9
A6: Section 232 Copper | B6: 0.3 | C6: 0.7 | D6: 0.7 | E6: 0.8 | F6: 0.8 | G6: 0.8 | H6: 0.9 | I6: 0.9 | J6: 0.9 | K6: 1 | L6: 1 | M6: 8.5
A7: Section 232 Furniture, Kithcen Cabinets and Vanities, Lumber | B7: 0.2 | C7: 1.1 | D7: 1.3 | E7: 1.3 | F7: 1.4 | G7: 1.4 | H7: 1.5 | I7: 1.5 | J7: 1.6 | K7: 1.7 | L7: 1.7 | M7: 14.4 | O7: tariff content, trend
A8: Section 232 Heavy Trucks and Parts | B8: -0.6 | C8: 5.5 | D8: 5.7 | E8: 6 | F8: 6.1 | G8: 6.4 | H8: 6.6 | I8: 6.8 | J8: 7.1 | K8: 7.4 | L8: 7.5 | M8: 65 | O8: other taxes
O9: corp tax
A10: Section 122 Tariff (10%) | B10: 0 | C10: 25.3 | D10: 0 | E10: 0 | F10: 0 | G10: 0 | H10: 0 | I10: 0 | J10: 0 | K10: 0 | L10: 0 | M10: 25.3 | O10: create financial chart
A11: Section 122 Tariff (15%) | B11: 0 | C11: 33.2 | D11: 0 | E11: 0 | F11: 0 | G11: 0 | H11: 0 | I11: 0 | J11: 0 | K11: 0 | L11: 0 | M11: 33.2 | O11: gdp changes
A13: Total | B13: 23.2 | C13: 76 | D13: 43.6 | E13: 45.3 | F13: 46 | G13: 47.7 | H13: 49.5 | I13: 50.9 | J13: 53.1 | K13: 54.9 | L13: 55.9 | M13: 522.8
A15: IEEPA Tariffs | B15: 72 | C15: 93.9 | D15: 95.7 | E15: 99.7 | F15: 101.9 | G15: 106.1 | H15: 110.3 | I15: 113.7 | J15: 118.7 | K15: 122.4 | L15: 125.1 | M15: 1087.5
A16: IEEPA Fentanyl China | B16: 23.1 | C16: 19 | D16: 19.6 | E16: 20.5 | F16: 20.9 | G16: 22 | H16: 22.7 | I16: 23.4 | J16: 24.5 | K16: 25.4 | L16: 25.9 | M16: 224
A17: IEEPA Mexico | B17: 1.9 | C17: 2.8 | D17: 2.9 | E17: 3 | F17: 3 | G17: 3.1 | H17: 3.2 | I17: 3.2 | J17: 3.3 | K17: 3.5 | L17: 3.5 | M17: 31.6
A18: IEEPA Canada | B18: 1.9 | C18: 3.1 | D18: 3.1 | E18: 3.2 | F18: 3.2 | G18: 3.3 | H18: 3.4 | I18: 3.5 | J18: 3.6 | K18: 3.7 | L18: 3.8 | M18: 33.8
A19: IEEPA 10% Baseline Tariff Excluding Canada and Mexico | B19: 35.4 | C19: 47.9 | D19: 49.2 | E19: 51.1 | F19: 52.5 | G19: 54.7 | H19: 56.9 | I19: 59.1 | J19: 61.6 | K19: 63.7 | L19: 65.5 | M19: 562.3
A20: IEEPA "Reciprocal" Tariff Increases (ROW) | B20: 6.4 | C20: 16.6 | D20: 16.6 | E20: 17.2 | F20: 17.6 | G20: 18.2 | H20: 19 | I20: 19.5 | J20: 20.4 | K20: 21 | L20: 21.5 | M20: 187.7
A21: Ending De Minimis | B21: 3.2 | C21: 4.5 | D21: 4.4 | E21: 4.6 | F21: 4.6 | G21: 4.8 | H21: 5 | I21: 5 | J21: 5.3 | K21: 5.1 | L21: 4.8 | M21: 48.2
A23: Retaliation | B23: -8.6 | C23: -9.6 | D23: -10.8 | E23: -11.6 | F23: -12.5 | G23: -13.2 | H23: -14 | I23: -14.9 | J23: -15.6 | K23: -16.4 | L23: -17.4 | M23: -136

Sheet Gov Debt
A1: observation_date | B1: GFDEBTN | D1: Year | E1: 2022 | F1: 2023 | G1: 2024 | H1: 2025
A2: 44562 | B2: 30400960 | E2: =B5 -> 31419689 | F2: =B9 -> 34001494 | G2: =B13 -> 36218605 | H2: 37637553
A3: 44652 | B3: 30568582
A4: 44743 | B4: 30928912
A5: 44835 | B5: 31419689
A6: 44927 | B6: 31458438
A7: 45017 | B7: 32332274
A8: 45108 | B8: 33167334
A9: 45200 | B9: 34001494
A10: 45292 | B10: 34586533
A11: 45383 | B11: 34831634
A12: 45474 | B12: 35464674
A13: 45566 | B13: 36218605
A14: 45658 | B14: 36214310
... A16: 45839 | B16: 37637553
A17: 45931
A18: 46023 | B18: 38514009
A21: Table 1-3. CBO's Baseline Projections of Federal Debt
A22: Billions of dollars
B24: Actual, 2025 | C24: 2026 | D24: 2027 | E24: 2028 | F24: 2029 | G24: 2030 | H24: 2031 | I24: 2032 | J24: 2033 | K24: 2034 | L24: 2035 | M24: 2036 | N24: 2037 | O24: 2038 | P24: 2039 | Q24: 2040 | R24: 2041 | S24: 2042 | T24: 2043 | U24: 2044 | V24: 2045 | W24: 2046 | X24: 2047 | Y24: 2048 | Z24: 2049 | AA24: 2050 | AB24: 2051 | AC24: 2052 | AD24: 2053 | AE24: 2054 | AF24: 2055
A25: Debt held by the public at the beginning of the year | B25: 28196 | C25: 30172 | D25: 32095 | E25: 34005 | F25: 36093 | G25: 38103 | H25: 40280 | I25: 42528 | J25: 44922 | K25: 47644 | L25: 50394 | M25: 53103
A27: Changes in debt held by the public
A28: Resulting from the deficit | B28: 1775 | C28: 1853 | D28: 1887 | E28: 2080 | F28: 2020 | G28: 2201 | H28: 2286 | I28: 2439 | J28: 2781 | K28: 2819 | L28: 2779 | M28: 3115
A29: Resulting from other means of financing | B29: 201 | C29: 70 | D29: 22 | E29: 9 | F29: -10 | G29: -24 | H29: -37 | I29: -45 | J29: -59 | K29: -69 | L29: -70 | M29: -66
A30: growth% | C30: =(C29-B29)/B29 -> -0.65174129 | D30: =(D29-C29)/C29 -> -0.68571429 | E30: =(E29-D29)/D29 -> -0.59090909 | F30: =(F29-E29)/E29 -> -2.1111111 | G30: =(G29-F29)/F29 -> 1.4 | H30: =(H29-G29)/G29 -> 0.54166667 | I30: =(I29-H29)/H29 -> 0.21621622 | J30: =(J29-I29)/I29 -> 0.31111111 | ... M30: =(M29-L29)/L29 -> -0.057142857
A31: Total | B31: 1977 | C31: 1923 | D31: 1909 | E31: 2088 | F31: 2010 | G31: 2177 | H31: 2249 | I31: 2394 | J31: 2722 | K31: 2750 | L31: 2709 | M31: 3049
A33: Debt held by the public at the end of the year
A34: In billions of dollars | B34: 30172 | C34: 32095 | D34: 34005 | E34: 36093 | F34: 38103 | G34: 40280 | H34: 42528 | I34: 44922 | J34: 47644 | K34: 50394 | L34: 53103 | M34: 56152
A35: As a percentage of GDP | B35: 99.4 | C35: 100.6 | D35: 102.1 | E35: 104.1 | F35: 105.8 | G35: 107.7 | H35: 109.6 | I35: 111.5 | J35: 114 | K35: 116.2 | L35: 118 | M35: 120.2
A37: Addendum:
A38: Federal financial assets | B38: 2259 | C38: 2329 | D38: 2351 | E38: 2360 | F38: 2350 | G38: 2327 | H38: 2290 | I38: 2244 | J38: 2185 | K38: 2116 | L38: 2047 | M38: 1981
A39: growth% | C39: =(C38-B38)/B38 -> 0.030987162 | D39: =(D38-C38)/C38 -> 0.0094461142 | E39: =(E38-D38)/D38 -> 0.0038281582 | F39: =(F38-E38)/E38 -> -0.0042372881 | G39: =(G38-F38)/F38 -> -0.009787234 | H39: =(H38-G38)/G38 -> -0.015900301 | I39: =(I38-H38)/H38 -> -0.020087336 | J39: =(J38-I38)/I38 -> -0.026292335 | ... M39: =(M38-L38)/L38 -> -0.032242306
A40: Debt minus financial assets
A41: In billions of dollars | B41: 27913 | C41: 29766 | D41: 31653 | E41: 33733 | F41: 35752 | G41: 37953 | H41: 40239 | I41: 42678 | J41: 45459 | K41: 48277 | L41: 51056 | M41: 54172
A42: As a percentage of GDP | B42: 91.9 | C42: 93.3 | D42: 95 | E42: 97.3 | F42: 99.3 | G42: 101.5 | H42: 103.7 | I42: 106 | J42: 108.8 | K42: 111.3 | L42: 113.4 | M42: 116
A44: Federal Reserve's holdings of debt held by the public | B44: 4201 | C44: 4540 | D44: 4973 | E44: 5484 | F44: 6048 | G44: 6595 | H44: 7067 | I44: 7537 | J44: 8004 | K44: 8496 | L44: 8981 | M44: 9466
A45: growth% | C45: =(C44-B44)/B44 -> 0.080695073 | D45: =(D44-C44)/C44 -> 0.095374449 | E45: =(E44-D44)/D44 -> 0.10275488 | F45: =(F44-E44)/E44 -> 0.10284464 | G45: =(G44-F44)/F44 -> 0.090443122 | H45: =(H44-G44)/G44 -> 0.071569371 | I45: =(I44-H44)/H44 -> 0.066506297 | J45: =(J44-I44)/I44 -> 0.061960992 | ... M45: =(M44-L44)/L44 -> 0.054002895
A46: Debt minus financial assets and Federal Reserve's holdings
A47: In billions of dollars | B47: 23712 | C47: 25226 | D47: 26680 | E47: 28249 | F47: 29704 | G47: 31358 | H47: 33172 | I47: 35141 | J47: 37455 | K47: 39782 | L47: 42075 | M47: 44706
A48: As a percentage of GDP | B48: 78.1 | C48: 79.1 | D48: 80.1 | E48: 81.5 | F48: 82.5 | G48: 83.9 | H48: 85.5 | I48: 87.2 | J48: 89.6 | K48: 91.7 | L48: 93.5 | M48: 95.7
...

Sheet Gov outlays
A1: This file presents data that supplement CBO’s February 2026 report The Budget and Economic Outlook: 2026 to 2036.
A2: www.cbo.gov/publication/61882
A5: Table 3-1. CBO's Baseline Projections of Outlays
N7: Total
B8: Actual, 2025 | C8: 2026 | D8: 2027 | E8: 2028 | F8: 2029 | G8: 2030 | H8: 2031 | I8: 2032 | J8: 2033 | K8: 2034 | L8: 2035 | M8: 2036 | N8: 2027– 2031 | O8: 2027– 2036
B9: In billions of dollars
A10: Mandatory
A11: Social Security | B11: 1575 | C11: 1666 | D11: 1769 | E11: 1875 | F11: 1979 | G11: 2083 | H11: 2190 | I11: 2298 | J11: 2409 | K11: 2519 | L11: 2632 | M11: 2747 | N11: 9895 | O11: 22500
A12: Medicare | B12: 1180 | C12: 1287 | D12: 1374 | E12: 1533 | F12: 1470 | G12: 1649 | H12: 1753 | I12: 1867 | J12: 2123 | K12: 2153 | L12: 2155 | M12: 2421 | N12: 7778 | O12: 18497
A13: Medicaid | B13: 668 | C13: 708 | D13: 726 | E13: 746 | F13: 754 | G13: 777 | H13: 804 | I13: 834 | J13: 870 | K13: 905 | L13: 941 | M13: 981 | N13: 3806 | O13: 8338
A14: Other spending | B14: 1114 | C14: 1281 | D14: 1327 | E14: 1284 | F14: 1326 | G14: 1371 | H14: 1377 | I14: 1400 | J14: 1466 | K14: 1472 | L14: 1458 | M14: 1555 | N14: 6685 | O14: 14036
A15: Offsetting receipts | B15: -370 | C15: -412 | D15: -413 | E15: -434 | F15: -462 | G15: -504 | H15: -541 | I15: -564 | J15: -591 | K15: -613 | L15: -642 | M15: -675 | N15: -2353 | O15: -5438
A16: Subtotal | B16: 4168 | C16: 4529 | D16: 4783 | E16: 5005 | F16: 5067 | G16: 5375 | H16: 5582 | I16: 5835 | J16: 6277 | K16: 6437 | L16: 6545 | M16: 7028 | N16: 25812 | O16: 57933
A18: Discretionary
A19: Defense | B19: 893 | C19: 885 | D19: 901 | E19: 928 | F19: 938 | G19: 966 | H19: 986 | I19: 1006 | J19: 1034 | K19: 1051 | L19: 1068 | M19: 1100 | N19: 4719 | O19: 9979
A20: Nondefense | B20: 980 | C20: 996 | D20: 981 | E20: 1001 | F20: 1010 | G20: 1023 | H20: 1039 | I20: 1057 | J20: 1076 | K20: 1096 | L20: 1119 | M20: 1144 | N20: 5053 | O20: 10545
A21: Subtotal | B21: 1872 | C21: 1880 | D21: 1882 | E21: 1929 | F21: 1948 | G21: 1989 | H21: 2024 | I21: 2063 | J21: 2111 | K21: 2147 | L21: 2187 | M21: 2244 | N21: 9772 | O21: 20524
A22: Net interest | B22: 970 | C22: 1039 | D22: 1108 | E22: 1218 | F22: 1324 | G22: 1432 | H22: 1548 | I22: 1670 | J22: 1784 | K22: 1904 | L22: 2019 | M22: 2144 | N22: 6630 | O22: 16152
A24: Total | B24: 7010 | C24: 7449 | D24: 7772 | E24: 8151 | F24: 8340 | G24: 8796 | H24: 9155 | I24: 9569 | J24: 10172 | K24: 10487 | L24: 10751 | M24: 11416 | N24: 42214 | O24: 94610
A25: On-budget | B25: 5578 | C25: 5928 | D25: 6151 | E25: 6426 | F25: 6513 | G25: 6864 | H25: 7113 | I25: 7409 | J25: 7911 | K25: 8125 | L25: 8286 | M25: 8847 | N25: 33066 | O25: 73644
A26: Off-budget | B26: 1432 | C26: 1521 | D26: 1621 | E26: 1725 | F26: 1827 | G26: 1932 | H26: 2043 | I26: 2160 | J26: 2261 | K26: 2363 | L26: 2465 | M26: 2569 | N26: 9147 | O26: 20965
A28: Addendum:
A29: Outlays adjusted to exclude timing shifts
A30: Mandatory outlays | B30: 4168 | C30: 4529 | D30: 4783 | E30: 4887 | F30: 5185 | G30: 5375 | H30: 5582 | I30: 5835 | J30: 6117 | K30: 6425 | L30: 6716 | M30: 7028 | N30: 25812 | O30: 57933
A31: Discretionary outlays | B31: 1872 | C31: 1880 | D31: 1882 | E31: 1923 | F31: 1954 | G31: 1989 | H31: 2024 | I31: 2063 | J31: 2105 | K31: 2147 | L31: 2194 | M31: 2244 | N31: 9772 | O31: 20524
A32: Total outlays | B32: 7010 | C32: 7449 | D32: 7772 | E32: 8028 | F32: 8463 | G32: 8796 | H32: 9155 | I32: 9569 | J32: 10006 | K32: 10475 | L32: 10929 | M32: 11416 | N32: 42214 | O32: 94610
A34: Gross domestic product | B34: 30362 | C34: 31902 | D34: 33315 | E34: 34666 | F34: 36010 | G34: 37391 | H34: 38813 | I34: 40277 | J34: 41796 | K34: 43373 | L34: 45012 | M34: 46712 | N34: 180195 | O34: 397364
B36: =B14/B34 -> 0.0366906 | C36: =C14/C34 -> 0.040154222 | D36: =D14/D34 -> 0.039831908 | E36: =E14/E34 -> 0.037039174 | F36: =F14/F34 -> 0.036823105 | G36: =G14/G34 -> 0.036666578 | H36: =H14/H34 -> 0.035477804 | I36: =I14/I34 -> 0.034759292 | ... M36: =M14/M34 -> 0.033289091
B37: =SUM(B14:B15)/B34 -> 0.024504315 | C37: =SUM(C14:C15)/C34 -> 0.027239671 | D37: =SUM(D14:D15)/D34 -> 0.027435089 | E37: =SUM(E14:E15)/E34 -> 0.024519702 | F37: =SUM(F14:F15)/F34 -> 0.023993335 | G37: =SUM(G14:G15)/G34 -> 0.023187398 | H37: =SUM(H14:H15)/H34 -> 0.021539175 | I37: =SUM(I14:I15)/I34 -> 0.020756263 | ... M37: =SUM(M14:M15)/M34 -> 0.018838842
C38: =(C14-B14)/B14 -> 0.14991023 | D38: =(D14-C14)/C14 -> 0.035909446 | E38: =(E14-D14)/D14 -> -0.032403919 | F38: =(F14-E14)/E14 -> 0.03271028 | G38: =(G14-F14)/F14 -> 0.033936652 | H38: =(H14-G14)/G14 -> 0.0043763676 | I38: =(I14-H14)/H14 -> 0.016702977 | J38: =(J14-I14)/I14 -> 0.047142857 | ... M38: =(M14-L14)/L14 -> 0.066529492
C39: =(C15-B15)/B15 -> 0.11351351 | D39: =(D15-C15)/C15 -> 0.0024271845 | E39: =(E15-D15)/D15 -> 0.050847458 | F39: =(F15-E15)/E15 -> 0.064516129 | G39: =(G15-F15)/F15 -> 0.090909091 | H39: =(H15-G15)/G15 -> 0.073412698 | I39: =(I15-H15)/H15 -> 0.042513863 | J39: =(J15-I15)/I15 -> 0.04787234 | ... M39: =(M15-L15)/L15 -> 0.051401869
F40: =GEOMEAN(C39:M39) -> 0.043704917
B69: Average 2011 - 2024 | C69: 0.042
B70: 2025 | C70: =B37 -> 0.024504315
B71: 2026 | C71: =C37 -> 0.027239671
B72: 2036 | C72: =M37 -> 0.018838842

Sheet Social Security
A2: SECTION 1: CURRENT BASELINE
A3: Metric | B3: Value | C3: Unit | D3: Source | E3: Notes
A4: FY2025 Social Security outlays | B4: 1647 | C4: $B | D4: CBO Baseline 2025 | E4: Up $127B (+8%) from FY2024
A5: 10-year projected OASDI shortfall (2026-2035) | B5: 2600 | C5: $B | D5: CBO / CRFB Mar 2025 | E5: Revenues fall $2.6T short of costs over next decade
A6: OASI trust fund depletion year | B6: 2033 | C6: Year | D6: 2025 Trustees Report | E6: Only 77% of scheduled benefits payable after depletion
A7: DI trust fund depletion year | B7: 2099 | C7: Year | D7: 2025 Trustees Report | E7: DI is solvent through at least 2099
A8: 2026 taxable maximum | B8: 184500 | C8: $ | D8: SSA COLA 2026 | E8: Up from $176,100 in 2025
A9: Current payroll tax rate (OASDI) | B9: 0.124 | C9: % | D9: IRC / SSA | E9: 6.2% employee + 6.2% employer
A10: Share of earnings currently taxable | B10: 0.82 | C10: % | D10: CBO 2025 | E10: 82% of covered earnings fall below the cap
A11: 75-year actuarial deficit (% of taxable payroll) | B11: 0.038 | C11: % | D11: 2025 Trustees Report | E11: Highest in nearly 50 years; nearly doubled since 2010
A12: 2026 COLA adjustment | B12: 0.028 | C12: % | D12: SSA Oct 2025 | E12: +2.8%, effective Jan 2026
A13: Payroll tax revenue (2023) | B13: 1100 | C13: $B | D13: SSA / PGPF | E13: 90% of total SS income
A15: SECTION 2: REVENUE-SIDE SOLUTIONS (TAX FIXES)
A16: Policy Option | B16: 10-Year Revenue Gain ($B) | C16: 75-Year Solvency Gap Closed | D16: Who Is Affected | E16: Key Trade-Off / Mechanism | F16: Source
A17: A. Raise taxable max to 90% of earnings (~$305,100) | B17: 800 | C17: 0.2 | D17: Top 18% of earners (above current $184,500 cap) | E17: Additional taxed earnings also increase future benefits for those earners, partially offsetting revenue gains | F17: CBO Budget Options 2024; CRFB Mar 2025
A18: B. Apply 12.4% tax on earnings > $250K ("donut hole," no benefit credit) | B18: 1600 | C18: 0.7 | D18: Top 6% of earners; gap between cap and $250K untaxed | E18: No benefit credit means pure revenue gain; most aggressive solvency fix among cap options | F18: CBO Budget Options; CRFB Mar 2025
A19: C. Eliminate the cap entirely (with benefit credit) | B19: 3200 | C19: 0.53 | D19: All earners above $184,500 (2026 cap) | E19: Largest gross revenue but future benefit obligations grow; net trust-fund gain smaller than 'no-credit' version | F19: SS Trustees; PGPF May 2025
